Workbook

Sheet Dashboard
A1: Netflix catalogue dashboard (public Netflix titles dataset)
A3: Titles | C3: Movie share | E3: Avg movie (min)
A4: =Analysis!B3 -> 6234 | C4: =Analysis!B6 -> 0.68415143 | E4: =Analysis!B7 -> 99.100821
A6: Key findings (live formulas)
A7: ="Peak year: "&INDEX(Analysis!A14:A26,MATCH(MAX(Analysis!D14:D26),Analysis!D14:D26,0))&" saw the most additions ("&TEXT(MAX(Analysis!D14:D26),"#,##0")&" titles)." -> Peak year: 2019 saw the most additions (2,349 titles).
A8: ="Mix: "&TEXT(Analysis!B6,"0%")&" of the catalogue is movies; the average movie runs "&TEXT(Analysis!B7,"0")&" minutes." -> Mix: 68% of the catalogue is movies; the average movie runs 99 minutes.
A9: ="Top country: "&Analysis!A31&" with "&TEXT(Analysis!C31,"0.0%")&" of all titles." -> Top country: United States with 36.9% of all titles.
A10: ="Top genre: "&Analysis!A45&" ("&TEXT(Analysis!C45,"0.0%")&")." -> Top genre: Dramas (17.3%).

Sheet Analysis
A1: Netflix catalogue analysis (cleaning done with formulas on the Data sheet)
D2: Cleaning log: missing values
A3: Titles | B3: =COUNTA(Data!$A$2:$A$6235) -> 6234 | D3: Column | E3: Blank cells | F3: % of titles
A4: Movies | B4: =COUNTIF(Data!$B$2:$B$6235,"Movie") -> 4265 | D4: director | E4: =COUNTBLANK(Data!$D$2:$D$6235) -> 1969 | F4: =IFERROR(E4/$B$3,0) -> 0.31584857
A5: TV shows | B5: =COUNTIF(Data!$B$2:$B$6235,"TV Show") -> 1969 | D5: country | E5: =COUNTBLANK(Data!$E$2:$E$6235) -> 476 | F5: =IFERROR(E5/$B$3,0) -> 0.07635547
A6: Movie share | B6: =IFERROR(B4/B3,0) -> 0.68415143 | D6: date_added | E6: =COUNTBLANK(Data!$F$2:$F$6235) -> 11 | F6: =IFERROR(E6/$B$3,0) -> 0.0017645172
A7: Avg movie length (min) | B7: =AVERAGE(Data!$N$2:$N$6235) -> 99.100821 | D7: rating | E7: =COUNTBLANK(Data!$H$2:$H$6235) -> 10 | F7: =IFERROR(E7/$B$3,0) -> 0.0016041065
A8: Avg TV seasons | B8: =AVERAGE(Data!$O$2:$O$6235) -> 1.7795835
A9: Avg years from release to added | B9: =AVERAGE(Data!$P$2:$P$6235) -> 4.6210831 | D9: Blank countries are labelled "Unknown"; rows with no date_added are left out of the year trend.
A12: Titles added per year
A13: Year | B13: Movies | C13: TV shows | D13: Total
A14: 2008 | B14: =COUNTIFS(Data!$K$2:$K$6235,$A14,Data!$B$2:$B$6235,"Movie") -> 1 | C14: =COUNTIFS(Data!$K$2:$K$6235,$A14,Data!$B$2:$B$6235,"TV Show") -> 1 | D14: =B14+C14 -> 2
A15: 2009 | B15: =COUNTIFS(Data!$K$2:$K$6235,$A15,Data!$B$2:$B$6235,"Movie") -> 2 | C15: =COUNTIFS(Data!$K$2:$K$6235,$A15,Data!$B$2:$B$6235,"TV Show") -> 0 | D15: =B15+C15 -> 2
A16: 2010 | B16: =COUNTIFS(Data!$K$2:$K$6235,$A16,Data!$B$2:$B$6235,"Movie") -> 1 | C16: =COUNTIFS(Data!$K$2:$K$6235,$A16,Data!$B$2:$B$6235,"TV Show") -> 0 | D16: =B16+C16 -> 1
A17: 2011 | B17: =COUNTIFS(Data!$K$2:$K$6235,$A17,Data!$B$2:$B$6235,"Movie") -> 13 | C17: =COUNTIFS(Data!$K$2:$K$6235,$A17,Data!$B$2:$B$6235,"TV Show") -> 0 | D17: =B17+C17 -> 13
A18: 2012 | B18: =COUNTIFS(Data!$K$2:$K$6235,$A18,Data!$B$2:$B$6235,"Movie") -> 4 | C18: =COUNTIFS(Data!$K$2:$K$6235,$A18,Data!$B$2:$B$6235,"TV Show") -> 3 | D18: =B18+C18 -> 7
A19: 2013 | B19: =COUNTIFS(Data!$K$2:$K$6235,$A19,Data!$B$2:$B$6235,"Movie") -> 6 | C19: =COUNTIFS(Data!$K$2:$K$6235,$A19,Data!$B$2:$B$6235,"TV Show") -> 6 | D19: =B19+C19 -> 12
A20: 2014 | B20: =COUNTIFS(Data!$K$2:$K$6235,$A20,Data!$B$2:$B$6235,"Movie") -> 19 | C20: =COUNTIFS(Data!$K$2:$K$6235,$A20,Data!$B$2:$B$6235,"TV Show") -> 6 | D20: =B20+C20 -> 25
A21: 2015 | B21: =COUNTIFS(Data!$K$2:$K$6235,$A21,Data!$B$2:$B$6235,"Movie") -> 58 | C21: =COUNTIFS(Data!$K$2:$K$6235,$A21,Data!$B$2:$B$6235,"TV Show") -> 32 | D21: =B21+C21 -> 90
A22: 2016 | B22: =COUNTIFS(Data!$K$2:$K$6235,$A22,Data!$B$2:$B$6235,"Movie") -> 264 | C22: =COUNTIFS(Data!$K$2:$K$6235,$A22,Data!$B$2:$B$6235,"TV Show") -> 192 | D22: =B22+C22 -> 456
A23: 2017 | B23: =COUNTIFS(Data!$K$2:$K$6235,$A23,Data!$B$2:$B$6235,"Movie") -> 913 | C23: =COUNTIFS(Data!$K$2:$K$6235,$A23,Data!$B$2:$B$6235,"TV Show") -> 387 | D23: =B23+C23 -> 1300
A24: 2018 | B24: =COUNTIFS(Data!$K$2:$K$6235,$A24,Data!$B$2:$B$6235,"Movie") -> 1290 | C24: =COUNTIFS(Data!$K$2:$K$6235,$A24,Data!$B$2:$B$6235,"TV Show") -> 492 | D24: =B24+C24 -> 1782
A25: 2019 | B25: =COUNTIFS(Data!$K$2:$K$6235,$A25,Data!$B$2:$B$6235,"Movie") -> 1546 | C25: =COUNTIFS(Data!$K$2:$K$6235,$A25,Data!$B$2:$B$6235,"TV Show") -> 803 | D25: =B25+C25 -> 2349
A26: 2020 | B26: =COUNTIFS(Data!$K$2:$K$6235,$A26,Data!$B$2:$B$6235,"Movie") -> 147 | C26: =COUNTIFS(Data!$K$2:$K$6235,$A26,Data!$B$2:$B$6235,"TV Show") -> 37 | D26: =B26+C26 -> 184
A29: Top 10 primary countries
A30: Category | B30: Titles | C30: Share of titles
A31: United States | B31: =COUNTIF(Data!$L$2:$L$6235,$A31) -> 2302 | C31: =IFERROR(B31/$B$3,0) -> 0.36926532
A32: India | B32: =COUNTIF(Data!$L$2:$L$6235,$A32) -> 808 | C32: =IFERROR(B32/$B$3,0) -> 0.12961181
A33: United Kingdom | B33: =COUNTIF(Data!$L$2:$L$6235,$A33) -> 483 | C33: =IFERROR(B33/$B$3,0) -> 0.077478345
A34: Canada | B34: =COUNTIF(Data!$L$2:$L$6235,$A34) -> 206 | C34: =IFERROR(B34/$B$3,0) -> 0.033044594
A35: Japan | B35: =COUNTIF(Data!$L$2:$L$6235,$A35) -> 184 | C35: =IFERROR(B35/$B$3,0) -> 0.02951556
A36: France | B36: =COUNTIF(Data!$L$2:$L$6235,$A36) -> 147 | C36: =IFERROR(B36/$B$3,0) -> 0.023580366
A37: South Korea | B37: =COUNTIF(Data!$L$2:$L$6235,$A37) -> 146 | C37: =IFERROR(B37/$B$3,0) -> 0.023419955
A38: Spain | B38: =COUNTIF(Data!$L$2:$L$6235,$A38) -> 139 | C38: =IFERROR(B38/$B$3,0) -> 0.022297081
A39: Mexico | B39: =COUNTIF(Data!$L$2:$L$6235,$A39) -> 99 | C39: =IFERROR(B39/$B$3,0) -> 0.015880654
A40: Australia | B40: =COUNTIF(Data!$L$2:$L$6235,$A40) -> 94 | C40: =IFERROR(B40/$B$3,0) -> 0.015078601
A43: Top 10 primary genres
A44: Category | B44: Titles | C44: Share of titles
A45: Dramas | B45: =COUNTIF(Data!$M$2:$M$6235,$A45) -> 1077 | C45: =IFERROR(B45/$B$3,0) -> 0.17276227
A46: Comedies | B46: =COUNTIF(Data!$M$2:$M$6235,$A46) -> 803 | C46: =IFERROR(B46/$B$3,0) -> 0.12880975
...

Sheet Data
A1: show_id | B1: type | C1: title | D1: director | E1: country | F1: date_added | G1: release_year | H1: rating | I1: duration | J1: listed_in | K1: Year added | L1: Primary country | M1: Primary genre | N1: Movie minutes | O1: TV seasons | P1: Years to add
A2: 81145628 | B2: Movie | C2: Norm of the North: King Sized Adventure | D2: Richard Finn, Tim Maltby | E2: United States, India, South Korea, China | F2: September 9, 2019 | G2: 2019 | H2: TV-PG | I2: 90 min | J2: Children & Family Movies, Comedies | K2: =IFERROR(VALUE(RIGHT(TRIM(F2),4)),"") -> 2019 | L2: =IF(TRIM(E2)="","Unknown",IFERROR(LEFT(TRIM(E2),FIND(",",TRIM(E2))-1),TRIM(E2))) -> United States | M2: =IFERROR(LEFT(J2,FIND(",",J2)-1),J2) -> Children & Family Movies | N2: =IF(B2="Movie",IFERROR(VALUE(LEFT(I2,FIND(" ",I2)-1)),""),"") -> 90 | O2: =IF(B2="TV Show",IFERROR(VALUE(LEFT(I2,FIND(" ",I2)-1)),""),"") | P2: =IF(K2="","",K2-G2) -> 0
A3: 80117401 | B3: Movie | C3: Jandino: Whatever it Takes | E3: United Kingdom | F3: September 9, 2016 | G3: 2016 | H3: TV-MA | I3: 94 min | J3: Stand-Up Comedy | K3: =IFERROR(VALUE(RIGHT(TRIM(F3),4)),"") -> 2016 | L3: =IF(TRIM(E3)="","Unknown",IFERROR(LEFT(TRIM(E3),FIND(",",TRIM(E3))-1),TRIM(E3))) -> United Kingdom | M3: =IFERROR(LEFT(J3,FIND(",",J3)-1),J3) -> Stand-Up Comedy | N3: =IF(B3="Movie",IFERROR(VALUE(LEFT(I3,FIND(" ",I3)-1)),""),"") -> 94 | O3: =IF(B3="TV Show",IFERROR(VALUE(LEFT(I3,FIND(" ",I3)-1)),""),"") | P3: =IF(K3="","",K3-G3) -> 0
A4: 70234439 | B4: TV Show | C4: Transformers Prime | E4: United States | F4: September 8, 2018 | G4: 2013 | H4: TV-Y7-FV | I4: 1 Season | J4: Kids' TV | K4: =IFERROR(VALUE(RIGHT(TRIM(F4),4)),"") -> 2018 | L4: =IF(TRIM(E4)="","Unknown",IFERROR(LEFT(TRIM(E4),FIND(",",TRIM(E4))-1),TRIM(E4))) -> United States | M4: =IFERROR(LEFT(J4,FIND(",",J4)-1),J4) -> Kids' TV | N4: =IF(B4="Movie",IFERROR(VALUE(LEFT(I4,FIND(" ",I4)-1)),""),"") | O4: =IF(B4="TV Show",IFERROR(VALUE(LEFT(I4,FIND(" ",I4)-1)),""),"") -> 1 | P4: =IF(K4="","",K4-G4) -> 5
A5: 80058654 | B5: TV Show | C5: Transformers: Robots in Disguise | E5: United States | F5: September 8, 2018 | G5: 2016 | H5: TV-Y7 | I5: 1 Season | J5: Kids' TV | K5: =IFERROR(VALUE(RIGHT(TRIM(F5),4)),"") -> 2018 | L5: =IF(TRIM(E5)="","Unknown",IFERROR(LEFT(TRIM(E5),FIND(",",TRIM(E5))-1),TRIM(E5))) -> United States | M5: =IFERROR(LEFT(J5,FIND(",",J5)-1),J5) -> Kids' TV | N5: =IF(B5="Movie",IFERROR(VALUE(LEFT(I5,FIND(" ",I5)-1)),""),"") | O5: =IF(B5="TV Show",IFERROR(VALUE(LEFT(I5,FIND(" ",I5)-1)),""),"") -> 1 | P5: =IF(K5="","",K5-G5) -> 2
A6: 80125979 | B6: Movie | C6: #realityhigh | D6: Fernando Lebrija | E6: United States | F6: September 8, 2017 | G6: 2017 | H6: TV-14 | I6: 99 min | J6: Comedies | K6: =IFERROR(VALUE(RIGHT(TRIM(F6),4)),"") -> 2017 | L6: =IF(TRIM(E6)="","Unknown",IFERROR(LEFT(TRIM(E6),FIND(",",TRIM(E6))-1),TRIM(E6))) -> United States | M6: =IFERROR(LEFT(J6,FIND(",",J6)-1),J6) -> Comedies | N6: =IF(B6="Movie",IFERROR(VALUE(LEFT(I6,FIND(" ",I6)-1)),""),"") -> 99 | O6: =IF(B6="TV Show",IFERROR(VALUE(LEFT(I6,FIND(" ",I6)-1)),""),"") | P6: =IF(K6="","",K6-G6) -> 0
A7: 80163890 | B7: TV Show | C7: Apaches | E7: Spain | F7: September 8, 2017 | G7: 2016 | H7: TV-MA | I7: 1 Season | J7: Crime TV Shows, International TV Shows, Spanish-Language TV Shows | K7: =IFERROR(VALUE(RIGHT(TRIM(F7),4)),"") -> 2017 | L7: =IF(TRIM(E7)="","Unknown",IFERROR(LEFT(TRIM(E7),FIND(",",TRIM(E7))-1),TRIM(E7))) -> Spain | M7: =IFERROR(LEFT(J7,FIND(",",J7)-1),J7) -> Crime TV Shows | N7: =IF(B7="Movie",IFERROR(VALUE(LEFT(I7,FIND(" ",I7)-1)),""),"") | O7: =IF(B7="TV Show",IFERROR(VALUE(LEFT(I7,FIND(" ",I7)-1)),""),"") -> 1 | P7: =IF(K7="","",K7-G7) -> 1
A8: 70304989 | B8: Movie | C8: Automata | D8: Gabe Ibáñez | E8: Bulgaria, United States, Spain, Canada | F8: September 8, 2017 | G8: 2014 | H8: R | I8: 110 min | J8: International Movies, Sci-Fi & Fantasy, Thrillers | K8: =IFERROR(VALUE(RIGHT(TRIM(F8),4)),"") -> 2017 | L8: =IF(TRIM(E8)="","Unknown",IFERROR(LEFT(TRIM(E8),FIND(",",TRIM(E8))-1),TRIM(E8))) -> Bulgaria | M8: =IFERROR(LEFT(J8,FIND(",",J8)-1),J8) -> International Movies | N8: =IF(B8="Movie",IFERROR(VALUE(LEFT(I8,FIND(" ",I8)-1)),""),"") -> 110 | O8: =IF(B8="TV Show",IFERROR(VALUE(LEFT(I8,FIND(" ",I8)-1)),""),"") | P8: =IF(K8="","",K8-G8) -> 3
A9: 80164077 | B9: Movie | C9: Fabrizio Copano: Solo pienso en mi | D9: Rodrigo Toro, Francisco Schultz | E9: Chile | F9: September 8, 2017 | G9: 2017 | H9: TV-MA | I9: 60 min | J9: Stand-Up Comedy | K9: =IFERROR(VALUE(RIGHT(TRIM(F9),4)),"") -> 2017 | L9: =IF(TRIM(E9)="","Unknown",IFERROR(LEFT(TRIM(E9),FIND(",",TRIM(E9))-1),TRIM(E9))) -> Chile | M9: =IFERROR(LEFT(J9,FIND(",",J9)-1),J9) -> Stand-Up Comedy | N9: =IF(B9="Movie",IFERROR(VALUE(LEFT(I9,FIND(" ",I9)-1)),""),"") -> 60 | O9: =IF(B9="TV Show",IFERROR(VALUE(LEFT(I9,FIND(" ",I9)-1)),""),"") | P9: =IF(K9="","",K9-G9) -> 0
A10: 80117902 | B10: TV Show | C10: Fire Chasers | E10: United States | F10: September 8, 2017 | G10: 2017 | H10: TV-MA | I10: 1 Season | J10: Docuseries, Science & Nature TV | K10: =IFERROR(VALUE(RIGHT(TRIM(F10),4)),"") -> 2017 | L10: =IF(TRIM(E10)="","Unknown",IFERROR(LEFT(TRIM(E10),FIND(",",TRIM(E10))-1),TRIM(E10))) -> United States | M10: =IFERROR(LEFT(J10,FIND(",",J10)-1),J10) -> Docuseries | N10: =IF(B10="Movie",IFERROR(VALUE(LEFT(I10,FIND(" ",I10)-1)),""),"") | O10: =IF(B10="TV Show",IFERROR(VALUE(LEFT(I10,FIND(" ",I10)-1)),""),"") -> 1 | P10: =IF(K10="","",K10-G10) -> 0
A11: 70304990 | B11: Movie | C11: Good People | D11: Henrik Ruben Genz | E11: United States, United Kingdom, Denmark, Sweden | F11: September 8, 2017 | G11: 2014 | H11: R | I11: 90 min | J11: Action & Adventure, Thrillers | K11: =IFERROR(VALUE(RIGHT(TRIM(F11),4)),"") -> 2017 | L11: =IF(TRIM(E11)="","Unknown",IFERROR(LEFT(TRIM(E11),FIND(",",TRIM(E11))-1),TRIM(E11))) -> United States | M11: =IFERROR(LEFT(J11,FIND(",",J11)-1),J11) -> Action & Adventure | N11: =IF(B11="Movie",IFERROR(VALUE(LEFT(I11,FIND(" ",I11)-1)),""),"") -> 90 | O11: =IF(B11="TV Show",IFERROR(VALUE(LEFT(I11,FIND(" ",I11)-1)),""),"") | P11: =IF(K11="","",K11-G11) -> 3
A12: 80169755 | B12: Movie | C12: Joaquín Reyes: Una y no más | D12: José Miguel Contreras | F12: September 8, 2017 | G12: 2017 | H12: TV-MA | I12: 78 min | J12: Stand-Up Comedy | K12: =IFERROR(VALUE(RIGHT(TRIM(F12),4)),"") -> 2017 | L12: =IF(TRIM(E12)="","Unknown",IFERROR(LEFT(TRIM(E12),FIND(",",TRIM(E12))-1),TRIM(E12))) -> Unknown | M12: =IFERROR(LEFT(J12,FIND(",",J12)-1),J12) -> Stand-Up Comedy | N12: =IF(B12="Movie",IFERROR(VALUE(LEFT(I12,FIND(" ",I12)-1)),""),"") -> 78 | O12: =IF(B12="TV Show",IFERROR(VALUE(LEFT(I12,FIND(" ",I12)-1)),""),"") | P12: =IF(K12="","",K12-G12) -> 0
A13: 70299204 | B13: Movie | C13: Kidnapping Mr. Heineken | D13: Daniel Alfredson | E13: Netherlands, Belgium, United Kingdom, United States | F13: September 8, 2017 | G13: 2015 | H13: R | I13: 95 min | J13: Action & Adventure, Dramas, International Movies | K13: =IFERROR(VALUE(RIGHT(TRIM(F13),4)),"") -> 2017 | L13: =IF(TRIM(E13)="","Unknown",IFERROR(LEFT(TRIM(E13),FIND(",",TRIM(E13))-1),TRIM(E13))) -> Netherlands | M13: =IFERROR(LEFT(J13,FIND(",",J13)-1),J13) -> Action & Adventure | N13: =IF(B13="Movie",IFERROR(VALUE(LEFT(I13,FIND(" ",I13)-1)),""),"") -> 95 | O13: =IF(B13="TV Show",IFERROR(VALUE(LEFT(I13,FIND(" ",I13)-1)),""),"") | P13: =IF(K13="","",K13-G13) -> 2
A14: 80182480 | B14: Movie | C14: Krish Trish and Baltiboy | F14: September 8, 2017 | G14: 2009 | H14: TV-Y7 | I14: 58 min | J14: Children & Family Movies | K14: =IFERROR(VALUE(RIGHT(TRIM(F14),4)),"") -> 2017 | L14: =IF(TRIM(E14)="","Unknown",IFERROR(LEFT(TRIM(E14),FIND(",",TRIM(E14))-1),TRIM(E14))) -> Unknown | M14: =IFERROR(LEFT(J14,FIND(",",J14)-1),J14) -> Children & Family Movies | N14: =IF(B14="Movie",IFERROR(VALUE(LEFT(I14,FIND(" ",I14)-1)),""),"") -> 58 | O14: =IF(B14="TV Show",IFERROR(VALUE(LEFT(I14,FIND(" ",I14)-1)),""),"") | P14: =IF(K14="","",K14-G14) -> 8
A15: 80182483 | B15: Movie | C15: Krish Trish and Baltiboy: Battle of Wits | D15: Munjal Shroff, Tilak Shetty | F15: September 8, 2017 | G15: 2013 | H15: TV-Y7 | I15: 62 min | J15: Children & Family Movies | K15: =IFERROR(VALUE(RIGHT(TRIM(F15),4)),"") -> 2017 | L15: =IF(TRIM(E15)="","Unknown",IFERROR(LEFT(TRIM(E15),FIND(",",TRIM(E15))-1),TRIM(E15))) -> Unknown | M15: =IFERROR(LEFT(J15,FIND(",",J15)-1),J15) -> Children & Family Movies | N15: =IF(B15="Movie",IFERROR(VALUE(LEFT(I15,FIND(" ",I15)-1)),""),"") -> 62 | O15: =IF(B15="TV Show",IFERROR(VALUE(LEFT(I15,FIND(" ",I15)-1)),""),"") | P15: =IF(K15="","",K15-G15) -> 4
A16: 80182596 | B16: Movie | C16: Krish Trish and Baltiboy: Best Friends Forever | D16: Munjal Shroff, Tilak Shetty | F16: September 8, 2017 | G16: 2016 | H16: TV-Y | I16: 65 min | J16: Children & Family Movies | K16: =IFERROR(VALUE(RIGHT(TRIM(F16),4)),"") -> 2017 | L16: =IF(TRIM(E16)="","Unknown",IFERROR(LEFT(TRIM(E16),FIND(",",TRIM(E16))-1),TRIM(E16))) -> Unknown | M16: =IFERROR(LEFT(J16,FIND(",",J16)-1),J16) -> Children & Family Movies | N16: =IF(B16="Movie",IFERROR(VALUE(LEFT(I16,FIND(" ",I16)-1)),""),"") -> 65 | O16: =IF(B16="TV Show",IFERROR(VALUE(LEFT(I16,FIND(" ",I16)-1)),""),"") | P16: =IF(K16="","",K16-G16) -> 1
A17: 80182482 | B17: Movie | C17: Krish Trish and Baltiboy: Comics of India | D17: Tilak Shetty | F17: September 8, 2017 | G17: 2012 | H17: TV-Y7 | I17: 61 min | J17: Children & Family Movies | K17: =IFERROR(VALUE(RIGHT(TRIM(F17),4)),"") -> 2017 | L17: =IF(TRIM(E17)="","Unknown",IFERROR(LEFT(TRIM(E17),FIND(",",TRIM(E17))-1),TRIM(E17))) -> Unknown | M17: =IFERROR(LEFT(J17,FIND(",",J17)-1),J17) -> Children & Family Movies | N17: =IF(B17="Movie",IFERROR(VALUE(LEFT(I17,FIND(" ",I17)-1)),""),"") -> 61 | O17: =IF(B17="TV Show",IFERROR(VALUE(LEFT(I17,FIND(" ",I17)-1)),""),"") | P17: =IF(K17="","",K17-G17) -> 5
A18: 80182597 | B18: Movie | C18: Krish Trish and Baltiboy: Oversmartness Never Pays | D18: Tilak Shetty | F18: September 8, 2017 | G18: 2017 | H18: TV-Y7 | I18: 65 min | J18: Children & Family Movies | K18: =IFERROR(VALUE(RIGHT(TRIM(F18),4)),"") -> 2017 | L18: =IF(TRIM(E18)="","Unknown",IFERROR(LEFT(TRIM(E18),FIND(",",TRIM(E18))-1),TRIM(E18))) -> Unknown | M18: =IFERROR(LEFT(J18,FIND(",",J18)-1),J18) -> Children & Family Movies | N18: =IF(B18="Movie",IFERROR(VALUE(LEFT(I18,FIND(" ",I18)-1)),""),"") -> 65 | O18: =IF(B18="TV Show",IFERROR(VALUE(LEFT(I18,FIND(" ",I18)-1)),""),"") | P18: =IF(K18="","",K18-G18) -> 0
A19: 80182481 | B19: Movie | C19: Krish Trish and Baltiboy: Part II | F19: September 8, 2017 | G19: 2010 | H19: TV-Y7 | I19: 58 min | J19: Children & Family Movies | K19: =IFERROR(VALUE(RIGHT(TRIM(F19),4)),"") -> 2017 | L19: =IF(TRIM(E19)="","Unknown",IFERROR(LEFT(TRIM(E19),FIND(",",TRIM(E19))-1),TRIM(E19))) -> Unknown | M19: =IFERROR(LEFT(J19,FIND(",",J19)-1),J19) -> Children & Family Movies | N19: =IF(B19="Movie",IFERROR(VALUE(LEFT(I19,FIND(" ",I19)-1)),""),"") -> 58 | O19: =IF(B19="TV Show",IFERROR(VALUE(LEFT(I19,FIND(" ",I19)-1)),""),"") | P19: =IF(K19="","",K19-G19) -> 7
A20: 80182621 | B20: Movie | C20: Krish Trish and Baltiboy: The Greatest Trick | D20: Munjal Shroff, Tilak Shetty | F20: September 8, 2017 | G20: 2013 | H20: TV-Y7 | I20: 60 min | J20: Children & Family Movies | K20: =IFERROR(VALUE(RIGHT(TRIM(F20),4)),"") -> 2017 | L20: =IF(TRIM(E20)="","Unknown",IFERROR(LEFT(TRIM(E20),FIND(",",TRIM(E20))-1),TRIM(E20))) -> Unknown | M20: =IFERROR(LEFT(J20,FIND(",",J20)-1),J20) -> Children & Family Movies | N20: =IF(B20="Movie",IFERROR(VALUE(LEFT(I20,FIND(" ",I20)-1)),""),"") -> 60 | O20: =IF(B20="TV Show",IFERROR(VALUE(LEFT(I20,FIND(" ",I20)-1)),""),"") | P20: =IF(K20="","",K20-G20) -> 4
A21: 80057969 | B21: Movie | C21: Love | D21: Gaspar Noé | E21: France, Belgium | F21: September 8, 2017 | G21: 2015 | H21: NR | I21: 135 min | J21: Cult Movies, Dramas, Independent Movies | K21: =IFERROR(VALUE(RIGHT(TRIM(F21),4)),"") -> 2017 | L21: =IF(TRIM(E21)="","Unknown",IFERROR(LEFT(TRIM(E21),FIND(",",TRIM(E21))-1),TRIM(E21))) -> France | M21: =IFERROR(LEFT(J21,FIND(",",J21)-1),J21) -> Cult Movies | N21: =IF(B21="Movie",IFERROR(VALUE(LEFT(I21,FIND(" ",I21)-1)),""),"") -> 135 | O21: =IF(B21="TV Show",IFERROR(VALUE(LEFT(I21,FIND(" ",I21)-1)),""),"") | P21: =IF(K21="","",K21-G21) -> 2
A22: 80060297 | B22: Movie | C22: Manhattan Romance | D22: Tom O'Brien | E22: United States | F22: September 8, 2017 | G22: 2014 | H22: TV-14 | I22: 98 min | J22: Comedies, Independent Movies, Romantic Movies | K22: =IFERROR(VALUE(RIGHT(TRIM(F22),4)),"") -> 2017 | L22: =IF(TRIM(E22)="","Unknown",IFERROR(LEFT(TRIM(E22),FIND(",",TRIM(E22))-1),TRIM(E22))) -> United States | M22: =IFERROR(LEFT(J22,FIND(",",J22)-1),J22) -> Comedies | N22: =IF(B22="Movie",IFERROR(VALUE(LEFT(I22,FIND(" ",I22)-1)),""),"") -> 98 | O22: =IF(B22="TV Show",IFERROR(VALUE(LEFT(I22,FIND(" ",I22)-1)),""),"") | P22: =IF(K22="","",K22-G22) -> 3
A23: 80046728 | B23: Movie | C23: Moonwalkers | D23: Antoine Bardou-Jacquet | E23: France, Belgium | F23: September 8, 2017 | G23: 2015 | H23: R | I23: 96 min | J23: Action & Adventure, Comedies, International Movies | K23: =IFERROR(VALUE(RIGHT(TRIM(F23),4)),"") -> 2017 | L23: =IF(TRIM(E23)="","Unknown",IFERROR(LEFT(TRIM(E23),FIND(",",TRIM(E23))-1),TRIM(E23))) -> France | M23: =IFERROR(LEFT(J23,FIND(",",J23)-1),J23) -> Action & Adventure | N23: =IF(B23="Movie",IFERROR(VALUE(LEFT(I23,FIND(" ",I23)-1)),""),"") -> 96 | O23: =IF(B23="TV Show",IFERROR(VALUE(LEFT(I23,FIND(" ",I23)-1)),""),"") | P23: =IF(K23="","",K23-G23) -> 2
A24: 80046727 | B24: Movie | C24: Rolling Papers | D24: Mitch Dickman | E24: United States, Uruguay | F24: September 8, 2017 | G24: 2015 | H24: TV-MA | I24: 79 min | J24: Documentaries | K24: =IFERROR(VALUE(RIGHT(TRIM(F24),4)),"") -> 2017 | L24: =IF(TRIM(E24)="","Unknown",IFERROR(LEFT(TRIM(E24),FIND(",",TRIM(E24))-1),TRIM(E24))) -> United States | M24: =IFERROR(LEFT(J24,FIND(",",J24)-1),J24) -> Documentaries | N24: =IF(B24="Movie",IFERROR(VALUE(LEFT(I24,FIND(" ",I24)-1)),""),"") -> 79 | O24: =IF(B24="TV Show",IFERROR(VALUE(LEFT(I24,FIND(" ",I24)-1)),""),"") | P24: =IF(K24="","",K24-G24) -> 2
A25: 70304988 | B25: Movie | C25: Stonehearst Asylum | D25: Brad Anderson | E25: United States | F25: September 8, 2017 | G25: 2014 | H25: PG-13 | I25: 113 min | J25: Horror Movies, Thrillers | K25: =IFERROR(VALUE(RIGHT(TRIM(F25),4)),"") -> 2017 | L25: =IF(TRIM(E25)="","Unknown",IFERROR(LEFT(TRIM(E25),FIND(",",TRIM(E25))-1),TRIM(E25))) -> United States | M25: =IFERROR(LEFT(J25,FIND(",",J25)-1),J25) -> Horror Movies | N25: =IF(B25="Movie",IFERROR(VALUE(LEFT(I25,FIND(" ",I25)-1)),""),"") -> 113 | O25: =IF(B25="TV Show",IFERROR(VALUE(LEFT(I25,FIND(" ",I25)-1)),""),"") | P25: =IF(K25="","",K25-G25) -> 3
A26: 80057700 | B26: Movie | C26: The Runner | D26: Austin Stark | E26: United States | F26: September 8, 2017 | G26: 2015 | H26: R | I26: 90 min | J26: Dramas, Independent Movies | K26: =IFERROR(VALUE(RIGHT(TRIM(F26),4)),"") -> 2017 | L26: =IF(TRIM(E26)="","Unknown",IFERROR(LEFT(TRIM(E26),FIND(",",TRIM(E26))-1),TRIM(E26))) -> United States | M26: =IFERROR(LEFT(J26,FIND(",",J26)-1),J26) -> Dramas | N26: =IF(B26="Movie",IFERROR(VALUE(LEFT(I26,FIND(" ",I26)-1)),""),"") -> 90 | O26: =IF(B26="TV Show",IFERROR(VALUE(LEFT(I26,FIND(" ",I26)-1)),""),"") | P26: =IF(K26="","",K26-G26) -> 2
A27: 80045922 | B27: Movie | C27: 6 Years | D27: Hannah Fidell | E27: United States | F27: September 8, 2015 | G27: 2015 | H27: NR | I27: 80 min | J27: Dramas, Independent Movies, Romantic Movies | K27: =IFERROR(VALUE(RIGHT(TRIM(F27),4)),"") -> 2015 | L27: =IF(TRIM(E27)="","Unknown",IFERROR(LEFT(TRIM(E27),FIND(",",TRIM(E27))-1),TRIM(E27))) -> United States | M27: =IFERROR(LEFT(J27,FIND(",",J27)-1),J27) -> Dramas | N27: =IF(B27="Movie",IFERROR(VALUE(LEFT(I27,FIND(" ",I27)-1)),""),"") -> 80 | O27: =IF(B27="TV Show",IFERROR(VALUE(LEFT(I27,FIND(" ",I27)-1)),""),"") | P27: =IF(K27="","",K27-G27) -> 0
A28: 80244601 | B28: TV Show | C28: Castle of Stars | F28: September 7, 2018 | G28: 2015 | H28: TV-14 | I28: 1 Season | J28: International TV Shows, Romantic TV Shows, TV Comedies | K28: =IFERROR(VALUE(RIGHT(TRIM(F28),4)),"") -> 2018 | L28: =IF(TRIM(E28)="","Unknown",IFERROR(LEFT(TRIM(E28),FIND(",",TRIM(E28))-1),TRIM(E28))) -> Unknown | M28: =IFERROR(LEFT(J28,FIND(",",J28)-1),J28) -> International TV Shows | N28: =IF(B28="Movie",IFERROR(VALUE(LEFT(I28,FIND(" ",I28)-1)),""),"") | O28: =IF(B28="TV Show",IFERROR(VALUE(LEFT(I28,FIND(" ",I28)-1)),""),"") -> 1 | P28: =IF(K28="","",K28-G28) -> 3
A29: 80203094 | B29: Movie | C29: City of Joy | D29: Madeleine Gavin | E29: United States, | F29: September 7, 2018 | G29: 2018 | H29: TV-MA | I29: 77 min | J29: Documentaries | K29: =IFERROR(VALUE(RIGHT(TRIM(F29),4)),"") -> 2018 | L29: =IF(TRIM(E29)="","Unknown",IFERROR(LEFT(TRIM(E29),FIND(",",TRIM(E29))-1),TRIM(E29))) -> United States | M29: =IFERROR(LEFT(J29,FIND(",",J29)-1),J29) -> Documentaries | N29: =IF(B29="Movie",IFERROR(VALUE(LEFT(I29,FIND(" ",I29)-1)),""),"") -> 77 | O29: =IF(B29="TV Show",IFERROR(VALUE(LEFT(I29,FIND(" ",I29)-1)),""),"") | P29: =IF(K29="","",K29-G29) -> 0
A30: 80190843 | B30: TV Show | C30: First and Last | F30: September 7, 2018 | G30: 2018 | H30: TV-MA | I30: 1 Season | J30: Docuseries | K30: =IFERROR(VALUE(RIGHT(TRIM(F30),4)),"") -> 2018 | L30: =IF(TRIM(E30)="","Unknown",IFERROR(LEFT(TRIM(E30),FIND(",",TRIM(E30))-1),TRIM(E30))) -> Unknown | M30: =IFERROR(LEFT(J30,FIND(",",J30)-1),J30) -> Docuseries | N30: =IF(B30="Movie",IFERROR(VALUE(LEFT(I30,FIND(" ",I30)-1)),""),"") | O30: =IF(B30="TV Show",IFERROR(VALUE(LEFT(I30,FIND(" ",I30)-1)),""),"") -> 1 | P30: =IF(K30="","",K30-G30) -> 0
A31: 70241607 | B31: Movie | C31: Laddaland | D31: Sopon Sukdapisit | E31: Thailand | F31: September 7, 2018 | G31: 2011 | H31: TV-MA | I31: 112 min | J31: Horror Movies, International Movies | K31: =IFERROR(VALUE(RIGHT(TRIM(F31),4)),"") -> 2018 | L31: =IF(TRIM(E31)="","Unknown",IFERROR(LEFT(TRIM(E31),FIND(",",TRIM(E31))-1),TRIM(E31))) -> Thailand | M31: =IFERROR(LEFT(J31,FIND(",",J31)-1),J31) -> Horror Movies | N31: =IF(B31="Movie",IFERROR(VALUE(LEFT(I31,FIND(" ",I31)-1)),""),"") -> 112 | O31: =IF(B31="TV Show",IFERROR(VALUE(LEFT(I31,FIND(" ",I31)-1)),""),"") | P31: =IF(K31="","",K31-G31) -> 7
A32: 80988892 | B32: Movie | C32: Next Gen | D32: Kevin R. Adams, Joe Ksander | E32: China, Canada, United States | F32: September 7, 2018 | G32: 2018 | H32: TV-PG | I32: 106 min | J32: Children & Family Movies, Comedies, Sci-Fi & Fantasy | K32: =IFERROR(VALUE(RIGHT(TRIM(F32),4)),"") -> 2018 | L32: =IF(TRIM(E32)="","Unknown",IFERROR(LEFT(TRIM(E32),FIND(",",TRIM(E32))-1),TRIM(E32))) -> China | M32: =IFERROR(LEFT(J32,FIND(",",J32)-1),J32) -> Children & Family Movies | N32: =IF(B32="Movie",IFERROR(VALUE(LEFT(I32,FIND(" ",I32)-1)),""),"") -> 106 | O32: =IF(B32="TV Show",IFERROR(VALUE(LEFT(I32,FIND(" ",I32)-1)),""),"") | P32: =IF(K32="","",K32-G32) -> 0
A33: 80239639 | B33: Movie | C33: Sierra Burgess Is A Loser | D33: Ian Samuels | E33: United States | F33: September 7, 2018 | G33: 2018 | H33: PG-13 | I33: 106 min | J33: Comedies, Romantic Movies | K33: =IFERROR(VALUE(RIGHT(TRIM(F33),4)),"") -> 2018 | L33: =IF(TRIM(E33)="","Unknown",IFERROR(LEFT(TRIM(E33),FIND(",",TRIM(E33))-1),TRIM(E33))) -> United States | M33: =IFERROR(LEFT(J33,FIND(",",J33)-1),J33) -> Comedies | N33: =IF(B33="Movie",IFERROR(VALUE(LEFT(I33,FIND(" ",I33)-1)),""),"") -> 106 | O33: =IF(B33="TV Show",IFERROR(VALUE(LEFT(I33,FIND(" ",I33)-1)),""),"") | P33: =IF(K33="","",K33-G33) -> 0
A34: 80159586 | B34: Movie | C34: The Most Assassinated Woman in the World | D34: Franck Ribière | E34: Belgium, United Kingdom, United States | F34: September 7, 2018 | G34: 2018 | H34: TV-MA | I34: 102 min | J34: Dramas, International Movies, Thrillers | K34: =IFERROR(VALUE(RIGHT(TRIM(F34),4)),"") -> 2018 | L34: =IF(TRIM(E34)="","Unknown",IFERROR(LEFT(TRIM(E34),FIND(",",TRIM(E34))-1),TRIM(E34))) -> Belgium | M34: =IFERROR(LEFT(J34,FIND(",",J34)-1),J34) -> Dramas | N34: =IF(B34="Movie",IFERROR(VALUE(LEFT(I34,FIND(" ",I34)-1)),""),"") -> 102 | O34: =IF(B34="TV Show",IFERROR(VALUE(LEFT(I34,FIND(" ",I34)-1)),""),"") | P34: =IF(K34="","",K34-G34) -> 0
A35: 80152447 | B35: Movie | C35: Cézanne et moi | D35: Daniele Thompson | E35: Belgium, France | F35: September 7, 2017 | G35: 2016 | H35: R | I35: 114 min | J35: Dramas, Independent Movies, International Movies | K35: =IFERROR(VALUE(RIGHT(TRIM(F35),4)),"") -> 2017 | L35: =IF(TRIM(E35)="","Unknown",IFERROR(LEFT(TRIM(E35),FIND(",",TRIM(E35))-1),TRIM(E35))) -> Belgium | M35: =IFERROR(LEFT(J35,FIND(",",J35)-1),J35) -> Dramas | N35: =IF(B35="Movie",IFERROR(VALUE(LEFT(I35,FIND(" ",I35)-1)),""),"") -> 114 | O35: =IF(B35="TV Show",IFERROR(VALUE(LEFT(I35,FIND(" ",I35)-1)),""),"") | P35: =IF(K35="","",K35-G35) -> 1
A36: 80221550 | B36: TV Show | C36: Archibald's Next Big Thing | F36: September 6, 2019 | G36: 2019 | H36: TV-Y7 | I36: 1 Season | J36: Kids' TV, TV Comedies | K36: =IFERROR(VALUE(RIGHT(TRIM(F36),4)),"") -> 2019 | L36: =IF(TRIM(E36)="","Unknown",IFERROR(LEFT(TRIM(E36),FIND(",",TRIM(E36))-1),TRIM(E36))) -> Unknown | M36: =IFERROR(LEFT(J36,FIND(",",J36)-1),J36) -> Kids' TV | N36: =IF(B36="Movie",IFERROR(VALUE(LEFT(I36,FIND(" ",I36)-1)),""),"") | O36: =IF(B36="TV Show",IFERROR(VALUE(LEFT(I36,FIND(" ",I36)-1)),""),"") -> 1 | P36: =IF(K36="","",K36-G36) -> 0
A37: 81154455 | B37: Movie | C37: Article 15 | D37: Anubhav Sinha | E37: India | F37: September 6, 2019 | G37: 2019 | H37: TV-MA | I37: 125 min | J37: Dramas, International Movies, Thrillers | K37: =IFERROR(VALUE(RIGHT(TRIM(F37),4)),"") -> 2019 | L37: =IF(TRIM(E37)="","Unknown",IFERROR(LEFT(TRIM(E37),FIND(",",TRIM(E37))-1),TRIM(E37))) -> India | M37: =IFERROR(LEFT(J37,FIND(",",J37)-1),J37) -> Dramas | N37: =IF(B37="Movie",IFERROR(VALUE(LEFT(I37,FIND(" ",I37)-1)),""),"") -> 125 | O37: =IF(B37="TV Show",IFERROR(VALUE(LEFT(I37,FIND(" ",I37)-1)),""),"") | P37: =IF(K37="","",K37-G37) -> 0
A38: 81113928 | B38: Movie | C38: Care of Kancharapalem | D38: Maha Venkatesh | F38: September 6, 2019 | G38: 2018 | H38: TV-14 | I38: 142 min | J38: Comedies, Dramas, Independent Movies | K38: =IFERROR(VALUE(RIGHT(TRIM(F38),4)),"") -> 2019 | L38: =IF(TRIM(E38)="","Unknown",IFERROR(LEFT(TRIM(E38),FIND(",",TRIM(E38))-1),TRIM(E38))) -> Unknown | M38: =IFERROR(LEFT(J38,FIND(",",J38)-1),J38) -> Comedies | N38: =IF(B38="Movie",IFERROR(VALUE(LEFT(I38,FIND(" ",I38)-1)),""),"") -> 142 | O38: =IF(B38="TV Show",IFERROR(VALUE(LEFT(I38,FIND(" ",I38)-1)),""),"") | P38: =IF(K38="","",K38-G38) -> 1
A39: 81052275 | B39: Movie | C39: Ee Nagaraniki Emaindi | D39: Tharun Bhascker | E39: India | F39: September 6, 2019 | G39: 2018 | H39: TV-14 | I39: 133 min | J39: Comedies, International Movies | K39: =IFERROR(VALUE(RIGHT(TRIM(F39),4)),"") -> 2019 | L39: =IF(TRIM(E39)="","Unknown",IFERROR(LEFT(TRIM(E39),FIND(",",TRIM(E39))-1),TRIM(E39))) -> India | M39: =IFERROR(LEFT(J39,FIND(",",J39)-1),J39) -> Comedies | N39: =IF(B39="Movie",IFERROR(VALUE(LEFT(I39,FIND(" ",I39)-1)),""),"") -> 133 | O39: =IF(B39="TV Show",IFERROR(VALUE(LEFT(I39,FIND(" ",I39)-1)),""),"") | P39: =IF(K39="","",K39-G39) -> 1
A40: 81132437 | B40: Movie | C40: Kill Me If You Dare | D40: Şenol Sönmez | F40: September 6, 2019 | G40: 2019 | H40: TV-14 | I40: 100 min | J40: Comedies, International Movies, Romantic Movies | K40: =IFERROR(VALUE(RIGHT(TRIM(F40),4)),"") -> 2019 | L40: =IF(TRIM(E40)="","Unknown",IFERROR(LEFT(TRIM(E40),FIND(",",TRIM(E40))-1),TRIM(E40))) -> Unknown | M40: =IFERROR(LEFT(J40,FIND(",",J40)-1),J40) -> Comedies | N40: =IF(B40="Movie",IFERROR(VALUE(LEFT(I40,FIND(" ",I40)-1)),""),"") -> 100 | O40: =IF(B40="TV Show",IFERROR(VALUE(LEFT(I40,FIND(" ",I40)-1)),""),"") | P40: =IF(K40="","",K40-G40) -> 0
...
